Traceback (most recent call last):
  File "/home/emilyjd/miniconda3/envs/cimr-devalgo-sid/lib/python3.9/site-packages/jupyter_cache/executors/utils.py", line 58, in single_nb_execution
    executenb(
  File "/home/emilyjd/miniconda3/envs/cimr-devalgo-sid/lib/python3.9/site-packages/nbclient/client.py", line 1314, in execute
    return NotebookClient(nb=nb, resources=resources, km=km, **kwargs).execute()
  File "/home/emilyjd/miniconda3/envs/cimr-devalgo-sid/lib/python3.9/site-packages/jupyter_core/utils/__init__.py", line 165, in wrapped
    return loop.run_until_complete(inner)
  File "/home/emilyjd/miniconda3/envs/cimr-devalgo-sid/lib/python3.9/asyncio/base_events.py", line 642, in run_until_complete
    return future.result()
  File "/home/emilyjd/miniconda3/envs/cimr-devalgo-sid/lib/python3.9/site-packages/nbclient/client.py", line 709, in async_execute
    await self.async_execute_cell(
  File "/home/emilyjd/miniconda3/envs/cimr-devalgo-sid/lib/python3.9/site-packages/nbclient/client.py", line 1062, in async_execute_cell
    await self._check_raise_for_error(cell, cell_index, exec_reply)
  File "/home/emilyjd/miniconda3/envs/cimr-devalgo-sid/lib/python3.9/site-packages/nbclient/client.py", line 918, in _check_raise_for_error
    raise CellExecutionError.from_cell_and_msg(cell, exec_reply_content)
nbclient.exceptions.CellExecutionError: An error occurred while executing the following cell:
------------------
# Reading in the data

varlist = ['driftX', 'driftY', 'status_flag']
iddata = nc_read(ncfile, varlist, skip=None, procfmt=True)
------------------


[0;31m---------------------------------------------------------------------------[0m
[0;31mFileNotFoundError[0m                         Traceback (most recent call last)
Cell [0;32mIn[7], line 4[0m
[1;32m      1[0m [38;5;66;03m# Reading in the data[39;00m
[1;32m      3[0m varlist [38;5;241m=[39m [[38;5;124m'[39m[38;5;124mdriftX[39m[38;5;124m'[39m, [38;5;124m'[39m[38;5;124mdriftY[39m[38;5;124m'[39m, [38;5;124m'[39m[38;5;124mstatus_flag[39m[38;5;124m'[39m]
[0;32m----> 4[0m iddata [38;5;241m=[39m [43mnc_read[49m[43m([49m[43mncfile[49m[43m,[49m[43m [49m[43mvarlist[49m[43m,[49m[43m [49m[43mskip[49m[38;5;241;43m=[39;49m[38;5;28;43;01mNone[39;49;00m[43m,[49m[43m [49m[43mprocfmt[49m[38;5;241;43m=[39;49m[38;5;28;43;01mTrue[39;49;00m[43m)[49m

Cell [0;32mIn[6], line 13[0m, in [0;36mnc_read[0;34m(ncfile, var, skip, procfmt)[0m
[1;32m     10[0m     v [38;5;241m=[39m var
[1;32m     12[0m [38;5;66;03m# Reading from the NetCDF file[39;00m
[0;32m---> 13[0m [38;5;28;01mwith[39;00m [43mDataset[49m[43m([49m[43mncfile[49m[43m,[49m[43m [49m[38;5;124;43m'[39;49m[38;5;124;43mr[39;49m[38;5;124;43m'[39;49m[43m)[49m [38;5;28;01mas[39;00m dataset:
[1;32m     15[0m     [38;5;28;01mtry[39;00m:
[1;32m     16[0m         ncdata[[38;5;124m'[39m[38;5;124mfv[39m[38;5;124m'[39m] [38;5;241m=[39m dataset[38;5;241m.[39mvariables[v][38;5;241m.[39m[38;5;18m__dict__[39m[[38;5;124m'[39m[38;5;124m_FillValue[39m[38;5;124m'[39m]

File [0;32msrc/netCDF4/_netCDF4.pyx:2449[0m, in [0;36mnetCDF4._netCDF4.Dataset.__init__[0;34m()[0m

File [0;32msrc/netCDF4/_netCDF4.pyx:2012[0m, in [0;36mnetCDF4._netCDF4._ensure_nc_success[0;34m()[0m

[0;31mFileNotFoundError[0m: [Errno 2] No such file or directory: '/home/emilyjd/SeaIceDrift_ATBD_v2/book/../../data/icedrift/cimr_devalgo_l2_sid_nh-ease2-250_radiometric.nc'

