Traceback (most recent call last):
  File "/home/emilyjd/miniconda3/envs/cimr-devalgo-sid/lib/python3.9/site-packages/nbclient/client.py", line 782, in _async_poll_for_reply
    msg = await ensure_async(self.kc.shell_channel.get_msg(timeout=new_timeout))
  File "/home/emilyjd/miniconda3/envs/cimr-devalgo-sid/lib/python3.9/site-packages/jupyter_core/utils/__init__.py", line 198, in ensure_async
    result = await obj
  File "/home/emilyjd/miniconda3/envs/cimr-devalgo-sid/lib/python3.9/site-packages/jupyter_client/channels.py", line 313, in get_msg
    raise Empty
_queue.Empty

During handling of the above exception, another exception occurred:

Traceback (most recent call last):
  File "/home/emilyjd/miniconda3/envs/cimr-devalgo-sid/lib/python3.9/site-packages/jupyter_cache/executors/utils.py", line 58, in single_nb_execution
    executenb(
  File "/home/emilyjd/miniconda3/envs/cimr-devalgo-sid/lib/python3.9/site-packages/nbclient/client.py", line 1314, in execute
    return NotebookClient(nb=nb, resources=resources, km=km, **kwargs).execute()
  File "/home/emilyjd/miniconda3/envs/cimr-devalgo-sid/lib/python3.9/site-packages/jupyter_core/utils/__init__.py", line 165, in wrapped
    return loop.run_until_complete(inner)
  File "/home/emilyjd/miniconda3/envs/cimr-devalgo-sid/lib/python3.9/asyncio/base_events.py", line 642, in run_until_complete
    return future.result()
  File "/home/emilyjd/miniconda3/envs/cimr-devalgo-sid/lib/python3.9/site-packages/nbclient/client.py", line 709, in async_execute
    await self.async_execute_cell(
  File "/home/emilyjd/miniconda3/envs/cimr-devalgo-sid/lib/python3.9/site-packages/nbclient/client.py", line 1005, in async_execute_cell
    exec_reply = await self.task_poll_for_reply
  File "/home/emilyjd/miniconda3/envs/cimr-devalgo-sid/lib/python3.9/site-packages/nbclient/client.py", line 806, in _async_poll_for_reply
    error_on_timeout_execute_reply = await self._async_handle_timeout(timeout, cell)
  File "/home/emilyjd/miniconda3/envs/cimr-devalgo-sid/lib/python3.9/site-packages/nbclient/client.py", line 856, in _async_handle_timeout
    raise CellTimeoutError.error_from_timeout_and_cell(
nbclient.exceptions.CellTimeoutError: A cell timed out while it was being executed, after 30 seconds.
The message was: Cell execution timed out.
Here is a preview of the cell contents:
-------------------
['%load_ext autoreload', '%autoreload', '', 'from icedrift_wrapper import icedrift_wrapper', 'rad = 100.']
...
['    warnings.simplefilter("ignore")', '', "    idrift = icedrift_wrapper(pdate, qdate, procpath, procpath, driftpath, os.path.join(logpath, 'cmcc-test.log'),", "                          'cimr-cimr', gridin.format(hemi), chan_list, rad, rad_neigh, ", '                          area_out=gridout.format(hemi))']
-------------------

